[2023-10-03T13:45:47.631+0000] {taskinstance.py:1125} INFO - Dependencies all met for dep_context=non-requeueable deps ti=<TaskInstance: capstone_project.create_dataset scheduled__2023-09-27T00:00:00+00:00 [queued]>
[2023-10-03T13:45:47.640+0000] {taskinstance.py:1125} INFO - Dependencies all met for dep_context=requeueable deps ti=<TaskInstance: capstone_project.create_dataset scheduled__2023-09-27T00:00:00+00:00 [queued]>
[2023-10-03T13:45:47.640+0000] {taskinstance.py:1331} INFO - Starting attempt 2 of 2
[2023-10-03T13:45:47.659+0000] {taskinstance.py:1350} INFO - Executing <Task(BigQueryCreateEmptyDatasetOperator): create_dataset> on 2023-09-27 00:00:00+00:00
[2023-10-03T13:45:47.666+0000] {standard_task_runner.py:57} INFO - Started process 1152 to run task
[2023-10-03T13:45:47.668+0000] {standard_task_runner.py:84} INFO - Running: ['***', 'tasks', 'run', 'capstone_project', 'create_dataset', 'scheduled__2023-09-27T00:00:00+00:00', '--job-id', '357', '--raw', '--subdir', 'DAGS_FOLDER/capstone_project.py', '--cfg-path', '/tmp/tmp4d035nv7']
[2023-10-03T13:45:47.670+0000] {standard_task_runner.py:85} INFO - Job 357: Subtask create_dataset
[2023-10-03T13:45:47.714+0000] {task_command.py:410} INFO - Running <TaskInstance: capstone_project.create_dataset scheduled__2023-09-27T00:00:00+00:00 [running]> on host 9a30478b5169
[2023-10-03T13:45:47.785+0000] {taskinstance.py:1570} INFO - Exporting env vars: AIRFLOW_CTX_DAG_OWNER='***' AIRFLOW_CTX_DAG_ID='capstone_project' AIRFLOW_CTX_TASK_ID='create_dataset' AIRFLOW_CTX_EXECUTION_DATE='2023-09-27T00:00:00+00:00' AIRFLOW_CTX_TRY_NUMBER='2' AIRFLOW_CTX_DAG_RUN_ID='scheduled__2023-09-27T00:00:00+00:00'
[2023-10-03T13:45:47.792+0000] {base.py:73} INFO - Using connection ID 'google_cloud_conn' for task execution.
[2023-10-03T13:45:47.843+0000] {bigquery.py:455} INFO - datasetId was not specified in `dataset_reference`. Will use default value maurits_dataset.
[2023-10-03T13:45:47.844+0000] {bigquery.py:455} INFO - projectId was not specified in `dataset_reference`. Will use default value aflow-training-rabo-2023-10-02.
[2023-10-03T13:45:47.844+0000] {bigquery.py:465} INFO - Creating dataset: maurits_dataset in project: aflow-training-rabo-2023-10-02 
[2023-10-03T13:45:48.167+0000] {bigquery.py:1855} INFO - Dataset maurits_dataset already exists.
[2023-10-03T13:45:48.176+0000] {taskinstance.py:1373} INFO - Marking task as SUCCESS. dag_id=capstone_project, task_id=create_dataset, execution_date=20230927T000000, start_date=20231003T134547, end_date=20231003T134548
[2023-10-03T13:45:48.242+0000] {local_task_job_runner.py:232} INFO - Task exited with return code 0
[2023-10-03T13:45:48.305+0000] {taskinstance.py:2674} INFO - 1 downstream tasks scheduled from follow-on schedule check
