[2023-10-03T12:51:29.691+0000] {taskinstance.py:1125} INFO - Dependencies all met for dep_context=non-requeueable deps ti=<TaskInstance: capstone_project.upload_file_to_gcs scheduled__2023-09-26T00:00:00+00:00 [queued]>
[2023-10-03T12:51:29.914+0000] {taskinstance.py:1125} INFO - Dependencies all met for dep_context=requeueable deps ti=<TaskInstance: capstone_project.upload_file_to_gcs scheduled__2023-09-26T00:00:00+00:00 [queued]>
[2023-10-03T12:51:29.917+0000] {taskinstance.py:1331} INFO - Starting attempt 1 of 1
[2023-10-03T12:51:30.082+0000] {taskinstance.py:1350} INFO - Executing <Task(LocalFilesystemToGCSOperator): upload_file_to_gcs> on 2023-09-26 00:00:00+00:00
[2023-10-03T12:51:30.179+0000] {standard_task_runner.py:57} INFO - Started process 407 to run task
[2023-10-03T12:51:30.210+0000] {standard_task_runner.py:84} INFO - Running: ['***', 'tasks', 'run', 'capstone_project', 'upload_file_to_gcs', 'scheduled__2023-09-26T00:00:00+00:00', '--job-id', '267', '--raw', '--subdir', 'DAGS_FOLDER/capstone_project.py', '--cfg-path', '/tmp/tmpa9n9655n']
[2023-10-03T12:51:30.273+0000] {standard_task_runner.py:85} INFO - Job 267: Subtask upload_file_to_gcs
[2023-10-03T12:51:31.674+0000] {task_command.py:410} INFO - Running <TaskInstance: capstone_project.upload_file_to_gcs scheduled__2023-09-26T00:00:00+00:00 [running]> on host 9a30478b5169
[2023-10-03T12:51:34.022+0000] {taskinstance.py:1570} INFO - Exporting env vars: AIRFLOW_CTX_DAG_OWNER='***' AIRFLOW_CTX_DAG_ID='capstone_project' AIRFLOW_CTX_TASK_ID='upload_file_to_gcs' AIRFLOW_CTX_EXECUTION_DATE='2023-09-26T00:00:00+00:00' AIRFLOW_CTX_TRY_NUMBER='1' AIRFLOW_CTX_DAG_RUN_ID='scheduled__2023-09-26T00:00:00+00:00'
[2023-10-03T12:51:34.607+0000] {taskinstance.py:1847} ERROR - Task failed with exception
Traceback (most recent call last):
  File "/home/airflow/.local/lib/python3.7/site-packages/airflow/providers/google/cloud/transfers/local_to_gcs.py", line 93, in execute
    impersonation_chain=self.impersonation_chain,
  File "/home/airflow/.local/lib/python3.7/site-packages/airflow/providers/google/cloud/hooks/gcs.py", line 165, in __init__
    impersonation_chain=impersonation_chain,
  File "/home/airflow/.local/lib/python3.7/site-packages/airflow/providers/google/common/hooks/base_google.py", line 234, in __init__
    self.extras: dict = self.get_connection(self.gcp_conn_id).extra_dejson
  File "/home/airflow/.local/lib/python3.7/site-packages/airflow/hooks/base.py", line 72, in get_connection
    conn = Connection.get_connection_from_secrets(conn_id)
  File "/home/airflow/.local/lib/python3.7/site-packages/airflow/models/connection.py", line 434, in get_connection_from_secrets
    raise AirflowNotFoundException(f"The conn_id `{conn_id}` isn't defined")
airflow.exceptions.AirflowNotFoundException: The conn_id `google_cloud_default` isn't defined
[2023-10-03T12:51:34.834+0000] {taskinstance.py:1373} INFO - Marking task as FAILED. dag_id=capstone_project, task_id=upload_file_to_gcs, execution_date=20230926T000000, start_date=20231003T125129, end_date=20231003T125134
[2023-10-03T12:51:35.375+0000] {standard_task_runner.py:109} ERROR - Failed to execute job 267 for task upload_file_to_gcs (The conn_id `google_cloud_default` isn't defined; 407)
[2023-10-03T12:51:35.896+0000] {local_task_job_runner.py:232} INFO - Task exited with return code 1
[2023-10-03T12:51:35.959+0000] {taskinstance.py:2674} INFO - 0 downstream tasks scheduled from follow-on schedule check
[2023-10-03T12:57:56.096+0000] {taskinstance.py:1125} INFO - Dependencies all met for dep_context=non-requeueable deps ti=<TaskInstance: capstone_project.upload_file_to_gcs scheduled__2023-09-26T00:00:00+00:00 [queued]>
[2023-10-03T12:57:56.130+0000] {taskinstance.py:1125} INFO - Dependencies all met for dep_context=requeueable deps ti=<TaskInstance: capstone_project.upload_file_to_gcs scheduled__2023-09-26T00:00:00+00:00 [queued]>
[2023-10-03T12:57:56.131+0000] {taskinstance.py:1331} INFO - Starting attempt 1 of 1
[2023-10-03T12:57:56.190+0000] {taskinstance.py:1350} INFO - Executing <Task(LocalFilesystemToGCSOperator): upload_file_to_gcs> on 2023-09-26 00:00:00+00:00
[2023-10-03T12:57:56.239+0000] {standard_task_runner.py:57} INFO - Started process 230 to run task
[2023-10-03T12:57:56.261+0000] {standard_task_runner.py:84} INFO - Running: ['***', 'tasks', 'run', 'capstone_project', 'upload_file_to_gcs', 'scheduled__2023-09-26T00:00:00+00:00', '--job-id', '326', '--raw', '--subdir', 'DAGS_FOLDER/capstone_project.py', '--cfg-path', '/tmp/tmpqvesm37z']
[2023-10-03T12:57:56.263+0000] {standard_task_runner.py:85} INFO - Job 326: Subtask upload_file_to_gcs
[2023-10-03T12:57:56.357+0000] {task_command.py:410} INFO - Running <TaskInstance: capstone_project.upload_file_to_gcs scheduled__2023-09-26T00:00:00+00:00 [running]> on host 9a30478b5169
[2023-10-03T12:57:56.530+0000] {taskinstance.py:1570} INFO - Exporting env vars: AIRFLOW_CTX_DAG_OWNER='***' AIRFLOW_CTX_DAG_ID='capstone_project' AIRFLOW_CTX_TASK_ID='upload_file_to_gcs' AIRFLOW_CTX_EXECUTION_DATE='2023-09-26T00:00:00+00:00' AIRFLOW_CTX_TRY_NUMBER='1' AIRFLOW_CTX_DAG_RUN_ID='scheduled__2023-09-26T00:00:00+00:00'
[2023-10-03T12:57:56.557+0000] {taskinstance.py:1847} ERROR - Task failed with exception
Traceback (most recent call last):
  File "/home/airflow/.local/lib/python3.7/site-packages/airflow/providers/google/cloud/transfers/local_to_gcs.py", line 93, in execute
    impersonation_chain=self.impersonation_chain,
  File "/home/airflow/.local/lib/python3.7/site-packages/airflow/providers/google/cloud/hooks/gcs.py", line 165, in __init__
    impersonation_chain=impersonation_chain,
  File "/home/airflow/.local/lib/python3.7/site-packages/airflow/providers/google/common/hooks/base_google.py", line 234, in __init__
    self.extras: dict = self.get_connection(self.gcp_conn_id).extra_dejson
  File "/home/airflow/.local/lib/python3.7/site-packages/airflow/hooks/base.py", line 72, in get_connection
    conn = Connection.get_connection_from_secrets(conn_id)
  File "/home/airflow/.local/lib/python3.7/site-packages/airflow/models/connection.py", line 434, in get_connection_from_secrets
    raise AirflowNotFoundException(f"The conn_id `{conn_id}` isn't defined")
airflow.exceptions.AirflowNotFoundException: The conn_id `GoogleBigQuery` isn't defined
[2023-10-03T12:57:56.563+0000] {taskinstance.py:1373} INFO - Marking task as FAILED. dag_id=capstone_project, task_id=upload_file_to_gcs, execution_date=20230926T000000, start_date=20231003T125756, end_date=20231003T125756
[2023-10-03T12:57:56.591+0000] {standard_task_runner.py:109} ERROR - Failed to execute job 326 for task upload_file_to_gcs (The conn_id `GoogleBigQuery` isn't defined; 230)
[2023-10-03T12:57:56.624+0000] {local_task_job_runner.py:232} INFO - Task exited with return code 1
[2023-10-03T12:57:56.650+0000] {taskinstance.py:2674} INFO - 0 downstream tasks scheduled from follow-on schedule check
