[2023-10-03T13:03:30.960+0000] {taskinstance.py:1125} INFO - Dependencies all met for dep_context=non-requeueable deps ti=<TaskInstance: capstone_project.upload_file_to_gcs scheduled__2023-09-26T00:00:00+00:00 [queued]>
[2023-10-03T13:03:31.032+0000] {taskinstance.py:1125} INFO - Dependencies all met for dep_context=requeueable deps ti=<TaskInstance: capstone_project.upload_file_to_gcs scheduled__2023-09-26T00:00:00+00:00 [queued]>
[2023-10-03T13:03:31.037+0000] {taskinstance.py:1331} INFO - Starting attempt 3 of 3
[2023-10-03T13:03:31.151+0000] {taskinstance.py:1350} INFO - Executing <Task(LocalFilesystemToGCSOperator): upload_file_to_gcs> on 2023-09-26 00:00:00+00:00
[2023-10-03T13:03:31.165+0000] {standard_task_runner.py:57} INFO - Started process 344 to run task
[2023-10-03T13:03:31.199+0000] {standard_task_runner.py:84} INFO - Running: ['***', 'tasks', 'run', 'capstone_project', 'upload_file_to_gcs', 'scheduled__2023-09-26T00:00:00+00:00', '--job-id', '333', '--raw', '--subdir', 'DAGS_FOLDER/capstone_project.py', '--cfg-path', '/tmp/tmpm81el0yi']
[2023-10-03T13:03:31.200+0000] {standard_task_runner.py:85} INFO - Job 333: Subtask upload_file_to_gcs
[2023-10-03T13:03:31.381+0000] {task_command.py:410} INFO - Running <TaskInstance: capstone_project.upload_file_to_gcs scheduled__2023-09-26T00:00:00+00:00 [running]> on host 9a30478b5169
[2023-10-03T13:03:31.730+0000] {taskinstance.py:1570} INFO - Exporting env vars: AIRFLOW_CTX_DAG_OWNER='***' AIRFLOW_CTX_DAG_ID='capstone_project' AIRFLOW_CTX_TASK_ID='upload_file_to_gcs' AIRFLOW_CTX_EXECUTION_DATE='2023-09-26T00:00:00+00:00' AIRFLOW_CTX_TRY_NUMBER='3' AIRFLOW_CTX_DAG_RUN_ID='scheduled__2023-09-26T00:00:00+00:00'
[2023-10-03T13:03:31.749+0000] {base.py:73} INFO - Using connection ID 'google_cloud_conn' for task execution.
[2023-10-03T13:03:31.757+0000] {taskinstance.py:1847} ERROR - Task failed with exception
Traceback (most recent call last):
  File "/home/airflow/.local/lib/python3.7/site-packages/airflow/providers/google/cloud/transfers/local_to_gcs.py", line 98, in execute
    raise FileNotFoundError(self.src)
FileNotFoundError: /tmp/{ ds }.parquet
[2023-10-03T13:03:31.778+0000] {taskinstance.py:1373} INFO - Marking task as FAILED. dag_id=capstone_project, task_id=upload_file_to_gcs, execution_date=20230926T000000, start_date=20231003T130330, end_date=20231003T130331
[2023-10-03T13:03:31.815+0000] {standard_task_runner.py:109} ERROR - Failed to execute job 333 for task upload_file_to_gcs (/tmp/{ ds }.parquet; 344)
[2023-10-03T13:03:31.861+0000] {local_task_job_runner.py:232} INFO - Task exited with return code 1
[2023-10-03T13:03:31.902+0000] {taskinstance.py:2674} INFO - 0 downstream tasks scheduled from follow-on schedule check
