[2023-10-03T09:40:13.753+0000] {taskinstance.py:1125} INFO - Dependencies all met for dep_context=non-requeueable deps ti=<TaskInstance: capstone_project.check_results scheduled__2023-09-24T00:00:00+00:00 [queued]>
[2023-10-03T09:40:13.785+0000] {taskinstance.py:1125} INFO - Dependencies all met for dep_context=requeueable deps ti=<TaskInstance: capstone_project.check_results scheduled__2023-09-24T00:00:00+00:00 [queued]>
[2023-10-03T09:40:13.787+0000] {taskinstance.py:1331} INFO - Starting attempt 1 of 1
[2023-10-03T09:40:13.847+0000] {taskinstance.py:1350} INFO - Executing <Task(PythonOperator): check_results> on 2023-09-24 00:00:00+00:00
[2023-10-03T09:40:13.857+0000] {standard_task_runner.py:57} INFO - Started process 1195 to run task
[2023-10-03T09:40:13.868+0000] {standard_task_runner.py:84} INFO - Running: ['***', 'tasks', 'run', 'capstone_project', 'check_results', 'scheduled__2023-09-24T00:00:00+00:00', '--job-id', '123', '--raw', '--subdir', 'DAGS_FOLDER/capstone_project.py', '--cfg-path', '/tmp/tmp9e6mqh4p']
[2023-10-03T09:40:13.872+0000] {standard_task_runner.py:85} INFO - Job 123: Subtask check_results
[2023-10-03T09:40:14.059+0000] {task_command.py:410} INFO - Running <TaskInstance: capstone_project.check_results scheduled__2023-09-24T00:00:00+00:00 [running]> on host 9a30478b5169
[2023-10-03T09:40:14.954+0000] {taskinstance.py:1570} INFO - Exporting env vars: AIRFLOW_CTX_DAG_OWNER='***' AIRFLOW_CTX_DAG_ID='capstone_project' AIRFLOW_CTX_TASK_ID='check_results' AIRFLOW_CTX_EXECUTION_DATE='2023-09-24T00:00:00+00:00' AIRFLOW_CTX_TRY_NUMBER='1' AIRFLOW_CTX_DAG_RUN_ID='scheduled__2023-09-24T00:00:00+00:00'
[2023-10-03T09:40:15.055+0000] {taskinstance.py:1847} ERROR - Task failed with exception
Traceback (most recent call last):
  File "/home/airflow/.local/lib/python3.7/site-packages/airflow/operators/python.py", line 181, in execute
    return_value = self.execute_callable()
  File "/home/airflow/.local/lib/python3.7/site-packages/airflow/operators/python.py", line 198, in execute_callable
    return self.python_callable(*self.op_args, **self.op_kwargs)
  File "/opt/airflow/dags/capstone_project.py", line 39, in _check_if_data_in_request
    response_dict = json.loads(response)
  File "/usr/local/lib/python3.7/json/__init__.py", line 341, in loads
    raise TypeError(f'the JSON object must be str, bytes or bytearray, '
TypeError: the JSON object must be str, bytes or bytearray, not NoneType
[2023-10-03T09:40:15.169+0000] {taskinstance.py:1373} INFO - Marking task as FAILED. dag_id=capstone_project, task_id=check_results, execution_date=20230924T000000, start_date=20231003T094013, end_date=20231003T094015
[2023-10-03T09:40:15.391+0000] {standard_task_runner.py:109} ERROR - Failed to execute job 123 for task check_results (the JSON object must be str, bytes or bytearray, not NoneType; 1195)
[2023-10-03T09:40:15.575+0000] {local_task_job_runner.py:232} INFO - Task exited with return code 1
[2023-10-03T09:40:15.768+0000] {taskinstance.py:2674} INFO - 0 downstream tasks scheduled from follow-on schedule check
