[2023-10-03T13:02:12.933+0000] {taskinstance.py:1125} INFO - Dependencies all met for dep_context=non-requeueable deps ti=<TaskInstance: capstone_project.upload_file_to_gcs scheduled__2023-09-25T00:00:00+00:00 [queued]>
[2023-10-03T13:02:12.988+0000] {taskinstance.py:1125} INFO - Dependencies all met for dep_context=requeueable deps ti=<TaskInstance: capstone_project.upload_file_to_gcs scheduled__2023-09-25T00:00:00+00:00 [queued]>
[2023-10-03T13:02:12.993+0000] {taskinstance.py:1331} INFO - Starting attempt 2 of 2
[2023-10-03T13:02:13.061+0000] {taskinstance.py:1350} INFO - Executing <Task(LocalFilesystemToGCSOperator): upload_file_to_gcs> on 2023-09-25 00:00:00+00:00
[2023-10-03T13:02:13.097+0000] {standard_task_runner.py:57} INFO - Started process 317 to run task
[2023-10-03T13:02:13.113+0000] {standard_task_runner.py:84} INFO - Running: ['***', 'tasks', 'run', 'capstone_project', 'upload_file_to_gcs', 'scheduled__2023-09-25T00:00:00+00:00', '--job-id', '332', '--raw', '--subdir', 'DAGS_FOLDER/capstone_project.py', '--cfg-path', '/tmp/tmp4fmtu1lk']
[2023-10-03T13:02:13.120+0000] {standard_task_runner.py:85} INFO - Job 332: Subtask upload_file_to_gcs
[2023-10-03T13:02:13.251+0000] {task_command.py:410} INFO - Running <TaskInstance: capstone_project.upload_file_to_gcs scheduled__2023-09-25T00:00:00+00:00 [running]> on host 9a30478b5169
[2023-10-03T13:02:13.411+0000] {taskinstance.py:1570} INFO - Exporting env vars: AIRFLOW_CTX_DAG_OWNER='***' AIRFLOW_CTX_DAG_ID='capstone_project' AIRFLOW_CTX_TASK_ID='upload_file_to_gcs' AIRFLOW_CTX_EXECUTION_DATE='2023-09-25T00:00:00+00:00' AIRFLOW_CTX_TRY_NUMBER='2' AIRFLOW_CTX_DAG_RUN_ID='scheduled__2023-09-25T00:00:00+00:00'
[2023-10-03T13:02:13.430+0000] {base.py:73} INFO - Using connection ID 'google_cloud_conn' for task execution.
[2023-10-03T13:02:13.449+0000] {taskinstance.py:1847} ERROR - Task failed with exception
Traceback (most recent call last):
  File "/home/airflow/.local/lib/python3.7/site-packages/airflow/providers/google/cloud/transfers/local_to_gcs.py", line 98, in execute
    raise FileNotFoundError(self.src)
FileNotFoundError: /tmp/{ 'ds' }.parquet
[2023-10-03T13:02:13.460+0000] {taskinstance.py:1373} INFO - Marking task as FAILED. dag_id=capstone_project, task_id=upload_file_to_gcs, execution_date=20230925T000000, start_date=20231003T130212, end_date=20231003T130213
[2023-10-03T13:02:13.483+0000] {standard_task_runner.py:109} ERROR - Failed to execute job 332 for task upload_file_to_gcs (/tmp/{ 'ds' }.parquet; 317)
[2023-10-03T13:02:13.525+0000] {local_task_job_runner.py:232} INFO - Task exited with return code 1
[2023-10-03T13:02:13.549+0000] {taskinstance.py:2674} INFO - 0 downstream tasks scheduled from follow-on schedule check
