[2023-10-03T12:51:29.620+0000] {taskinstance.py:1125} INFO - Dependencies all met for dep_context=non-requeueable deps ti=<TaskInstance: capstone_project.upload_file_to_gcs scheduled__2023-09-25T00:00:00+00:00 [queued]>
[2023-10-03T12:51:29.893+0000] {taskinstance.py:1125} INFO - Dependencies all met for dep_context=requeueable deps ti=<TaskInstance: capstone_project.upload_file_to_gcs scheduled__2023-09-25T00:00:00+00:00 [queued]>
[2023-10-03T12:51:29.894+0000] {taskinstance.py:1331} INFO - Starting attempt 1 of 1
[2023-10-03T12:51:30.222+0000] {taskinstance.py:1350} INFO - Executing <Task(LocalFilesystemToGCSOperator): upload_file_to_gcs> on 2023-09-25 00:00:00+00:00
[2023-10-03T12:51:30.424+0000] {standard_task_runner.py:57} INFO - Started process 418 to run task
[2023-10-03T12:51:30.483+0000] {standard_task_runner.py:84} INFO - Running: ['***', 'tasks', 'run', 'capstone_project', 'upload_file_to_gcs', 'scheduled__2023-09-25T00:00:00+00:00', '--job-id', '262', '--raw', '--subdir', 'DAGS_FOLDER/capstone_project.py', '--cfg-path', '/tmp/tmpn0u9f324']
[2023-10-03T12:51:30.664+0000] {standard_task_runner.py:85} INFO - Job 262: Subtask upload_file_to_gcs
[2023-10-03T12:51:31.982+0000] {task_command.py:410} INFO - Running <TaskInstance: capstone_project.upload_file_to_gcs scheduled__2023-09-25T00:00:00+00:00 [running]> on host 9a30478b5169
[2023-10-03T12:51:34.449+0000] {taskinstance.py:1570} INFO - Exporting env vars: AIRFLOW_CTX_DAG_OWNER='***' AIRFLOW_CTX_DAG_ID='capstone_project' AIRFLOW_CTX_TASK_ID='upload_file_to_gcs' AIRFLOW_CTX_EXECUTION_DATE='2023-09-25T00:00:00+00:00' AIRFLOW_CTX_TRY_NUMBER='1' AIRFLOW_CTX_DAG_RUN_ID='scheduled__2023-09-25T00:00:00+00:00'
[2023-10-03T12:51:34.800+0000] {taskinstance.py:1847} ERROR - Task failed with exception
Traceback (most recent call last):
  File "/home/airflow/.local/lib/python3.7/site-packages/airflow/providers/google/cloud/transfers/local_to_gcs.py", line 93, in execute
    impersonation_chain=self.impersonation_chain,
  File "/home/airflow/.local/lib/python3.7/site-packages/airflow/providers/google/cloud/hooks/gcs.py", line 165, in __init__
    impersonation_chain=impersonation_chain,
  File "/home/airflow/.local/lib/python3.7/site-packages/airflow/providers/google/common/hooks/base_google.py", line 234, in __init__
    self.extras: dict = self.get_connection(self.gcp_conn_id).extra_dejson
  File "/home/airflow/.local/lib/python3.7/site-packages/airflow/hooks/base.py", line 72, in get_connection
    conn = Connection.get_connection_from_secrets(conn_id)
  File "/home/airflow/.local/lib/python3.7/site-packages/airflow/models/connection.py", line 434, in get_connection_from_secrets
    raise AirflowNotFoundException(f"The conn_id `{conn_id}` isn't defined")
airflow.exceptions.AirflowNotFoundException: The conn_id `google_cloud_default` isn't defined
[2023-10-03T12:51:34.836+0000] {taskinstance.py:1373} INFO - Marking task as FAILED. dag_id=capstone_project, task_id=upload_file_to_gcs, execution_date=20230925T000000, start_date=20231003T125129, end_date=20231003T125134
[2023-10-03T12:51:34.905+0000] {standard_task_runner.py:109} ERROR - Failed to execute job 262 for task upload_file_to_gcs (The conn_id `google_cloud_default` isn't defined; 418)
[2023-10-03T12:51:35.042+0000] {local_task_job_runner.py:232} INFO - Task exited with return code 1
[2023-10-03T12:51:35.704+0000] {taskinstance.py:2674} INFO - 0 downstream tasks scheduled from follow-on schedule check
[2023-10-03T12:57:56.804+0000] {taskinstance.py:1125} INFO - Dependencies all met for dep_context=non-requeueable deps ti=<TaskInstance: capstone_project.upload_file_to_gcs scheduled__2023-09-25T00:00:00+00:00 [queued]>
[2023-10-03T12:57:56.843+0000] {taskinstance.py:1125} INFO - Dependencies all met for dep_context=requeueable deps ti=<TaskInstance: capstone_project.upload_file_to_gcs scheduled__2023-09-25T00:00:00+00:00 [queued]>
[2023-10-03T12:57:56.843+0000] {taskinstance.py:1331} INFO - Starting attempt 1 of 1
[2023-10-03T12:57:56.906+0000] {taskinstance.py:1350} INFO - Executing <Task(LocalFilesystemToGCSOperator): upload_file_to_gcs> on 2023-09-25 00:00:00+00:00
[2023-10-03T12:57:56.926+0000] {standard_task_runner.py:57} INFO - Started process 232 to run task
[2023-10-03T12:57:56.930+0000] {standard_task_runner.py:84} INFO - Running: ['***', 'tasks', 'run', 'capstone_project', 'upload_file_to_gcs', 'scheduled__2023-09-25T00:00:00+00:00', '--job-id', '328', '--raw', '--subdir', 'DAGS_FOLDER/capstone_project.py', '--cfg-path', '/tmp/tmp5t89badv']
[2023-10-03T12:57:56.931+0000] {standard_task_runner.py:85} INFO - Job 328: Subtask upload_file_to_gcs
[2023-10-03T12:57:56.987+0000] {task_command.py:410} INFO - Running <TaskInstance: capstone_project.upload_file_to_gcs scheduled__2023-09-25T00:00:00+00:00 [running]> on host 9a30478b5169
[2023-10-03T12:57:57.077+0000] {taskinstance.py:1570} INFO - Exporting env vars: AIRFLOW_CTX_DAG_OWNER='***' AIRFLOW_CTX_DAG_ID='capstone_project' AIRFLOW_CTX_TASK_ID='upload_file_to_gcs' AIRFLOW_CTX_EXECUTION_DATE='2023-09-25T00:00:00+00:00' AIRFLOW_CTX_TRY_NUMBER='1' AIRFLOW_CTX_DAG_RUN_ID='scheduled__2023-09-25T00:00:00+00:00'
[2023-10-03T12:57:57.098+0000] {taskinstance.py:1847} ERROR - Task failed with exception
Traceback (most recent call last):
  File "/home/airflow/.local/lib/python3.7/site-packages/airflow/providers/google/cloud/transfers/local_to_gcs.py", line 93, in execute
    impersonation_chain=self.impersonation_chain,
  File "/home/airflow/.local/lib/python3.7/site-packages/airflow/providers/google/cloud/hooks/gcs.py", line 165, in __init__
    impersonation_chain=impersonation_chain,
  File "/home/airflow/.local/lib/python3.7/site-packages/airflow/providers/google/common/hooks/base_google.py", line 234, in __init__
    self.extras: dict = self.get_connection(self.gcp_conn_id).extra_dejson
  File "/home/airflow/.local/lib/python3.7/site-packages/airflow/hooks/base.py", line 72, in get_connection
    conn = Connection.get_connection_from_secrets(conn_id)
  File "/home/airflow/.local/lib/python3.7/site-packages/airflow/models/connection.py", line 434, in get_connection_from_secrets
    raise AirflowNotFoundException(f"The conn_id `{conn_id}` isn't defined")
airflow.exceptions.AirflowNotFoundException: The conn_id `GoogleBigQuery` isn't defined
[2023-10-03T12:57:57.102+0000] {taskinstance.py:1373} INFO - Marking task as FAILED. dag_id=capstone_project, task_id=upload_file_to_gcs, execution_date=20230925T000000, start_date=20231003T125756, end_date=20231003T125757
[2023-10-03T12:57:57.117+0000] {standard_task_runner.py:109} ERROR - Failed to execute job 328 for task upload_file_to_gcs (The conn_id `GoogleBigQuery` isn't defined; 232)
[2023-10-03T12:57:57.140+0000] {local_task_job_runner.py:232} INFO - Task exited with return code 1
[2023-10-03T12:57:57.155+0000] {taskinstance.py:2674} INFO - 0 downstream tasks scheduled from follow-on schedule check
