[2023-10-03T12:51:29.689+0000] {taskinstance.py:1125} INFO - Dependencies all met for dep_context=non-requeueable deps ti=<TaskInstance: capstone_project.upload_file_to_gcs scheduled__2023-09-27T00:00:00+00:00 [queued]>
[2023-10-03T12:51:29.878+0000] {taskinstance.py:1125} INFO - Dependencies all met for dep_context=requeueable deps ti=<TaskInstance: capstone_project.upload_file_to_gcs scheduled__2023-09-27T00:00:00+00:00 [queued]>
[2023-10-03T12:51:29.883+0000] {taskinstance.py:1331} INFO - Starting attempt 1 of 1
[2023-10-03T12:51:30.102+0000] {taskinstance.py:1350} INFO - Executing <Task(LocalFilesystemToGCSOperator): upload_file_to_gcs> on 2023-09-27 00:00:00+00:00
[2023-10-03T12:51:30.213+0000] {standard_task_runner.py:57} INFO - Started process 408 to run task
[2023-10-03T12:51:30.338+0000] {standard_task_runner.py:84} INFO - Running: ['***', 'tasks', 'run', 'capstone_project', 'upload_file_to_gcs', 'scheduled__2023-09-27T00:00:00+00:00', '--job-id', '268', '--raw', '--subdir', 'DAGS_FOLDER/capstone_project.py', '--cfg-path', '/tmp/tmp0bf35dzn']
[2023-10-03T12:51:30.405+0000] {standard_task_runner.py:85} INFO - Job 268: Subtask upload_file_to_gcs
[2023-10-03T12:51:31.614+0000] {task_command.py:410} INFO - Running <TaskInstance: capstone_project.upload_file_to_gcs scheduled__2023-09-27T00:00:00+00:00 [running]> on host 9a30478b5169
[2023-10-03T12:51:33.957+0000] {taskinstance.py:1570} INFO - Exporting env vars: AIRFLOW_CTX_DAG_OWNER='***' AIRFLOW_CTX_DAG_ID='capstone_project' AIRFLOW_CTX_TASK_ID='upload_file_to_gcs' AIRFLOW_CTX_EXECUTION_DATE='2023-09-27T00:00:00+00:00' AIRFLOW_CTX_TRY_NUMBER='1' AIRFLOW_CTX_DAG_RUN_ID='scheduled__2023-09-27T00:00:00+00:00'
[2023-10-03T12:51:34.518+0000] {taskinstance.py:1847} ERROR - Task failed with exception
Traceback (most recent call last):
  File "/home/airflow/.local/lib/python3.7/site-packages/airflow/providers/google/cloud/transfers/local_to_gcs.py", line 93, in execute
    impersonation_chain=self.impersonation_chain,
  File "/home/airflow/.local/lib/python3.7/site-packages/airflow/providers/google/cloud/hooks/gcs.py", line 165, in __init__
    impersonation_chain=impersonation_chain,
  File "/home/airflow/.local/lib/python3.7/site-packages/airflow/providers/google/common/hooks/base_google.py", line 234, in __init__
    self.extras: dict = self.get_connection(self.gcp_conn_id).extra_dejson
  File "/home/airflow/.local/lib/python3.7/site-packages/airflow/hooks/base.py", line 72, in get_connection
    conn = Connection.get_connection_from_secrets(conn_id)
  File "/home/airflow/.local/lib/python3.7/site-packages/airflow/models/connection.py", line 434, in get_connection_from_secrets
    raise AirflowNotFoundException(f"The conn_id `{conn_id}` isn't defined")
airflow.exceptions.AirflowNotFoundException: The conn_id `google_cloud_default` isn't defined
[2023-10-03T12:51:34.820+0000] {taskinstance.py:1373} INFO - Marking task as FAILED. dag_id=capstone_project, task_id=upload_file_to_gcs, execution_date=20230927T000000, start_date=20231003T125129, end_date=20231003T125134
[2023-10-03T12:51:35.256+0000] {standard_task_runner.py:109} ERROR - Failed to execute job 268 for task upload_file_to_gcs (The conn_id `google_cloud_default` isn't defined; 408)
[2023-10-03T12:51:35.876+0000] {local_task_job_runner.py:232} INFO - Task exited with return code 1
[2023-10-03T12:51:36.187+0000] {taskinstance.py:2674} INFO - 0 downstream tasks scheduled from follow-on schedule check
[2023-10-03T12:57:55.314+0000] {taskinstance.py:1125} INFO - Dependencies all met for dep_context=non-requeueable deps ti=<TaskInstance: capstone_project.upload_file_to_gcs scheduled__2023-09-27T00:00:00+00:00 [queued]>
[2023-10-03T12:57:55.357+0000] {taskinstance.py:1125} INFO - Dependencies all met for dep_context=requeueable deps ti=<TaskInstance: capstone_project.upload_file_to_gcs scheduled__2023-09-27T00:00:00+00:00 [queued]>
[2023-10-03T12:57:55.358+0000] {taskinstance.py:1331} INFO - Starting attempt 1 of 1
[2023-10-03T12:57:55.422+0000] {taskinstance.py:1350} INFO - Executing <Task(LocalFilesystemToGCSOperator): upload_file_to_gcs> on 2023-09-27 00:00:00+00:00
[2023-10-03T12:57:55.433+0000] {standard_task_runner.py:57} INFO - Started process 229 to run task
[2023-10-03T12:57:55.453+0000] {standard_task_runner.py:84} INFO - Running: ['***', 'tasks', 'run', 'capstone_project', 'upload_file_to_gcs', 'scheduled__2023-09-27T00:00:00+00:00', '--job-id', '325', '--raw', '--subdir', 'DAGS_FOLDER/capstone_project.py', '--cfg-path', '/tmp/tmpr9opwt55']
[2023-10-03T12:57:55.459+0000] {standard_task_runner.py:85} INFO - Job 325: Subtask upload_file_to_gcs
[2023-10-03T12:57:55.609+0000] {task_command.py:410} INFO - Running <TaskInstance: capstone_project.upload_file_to_gcs scheduled__2023-09-27T00:00:00+00:00 [running]> on host 9a30478b5169
[2023-10-03T12:57:55.832+0000] {taskinstance.py:1570} INFO - Exporting env vars: AIRFLOW_CTX_DAG_OWNER='***' AIRFLOW_CTX_DAG_ID='capstone_project' AIRFLOW_CTX_TASK_ID='upload_file_to_gcs' AIRFLOW_CTX_EXECUTION_DATE='2023-09-27T00:00:00+00:00' AIRFLOW_CTX_TRY_NUMBER='1' AIRFLOW_CTX_DAG_RUN_ID='scheduled__2023-09-27T00:00:00+00:00'
[2023-10-03T12:57:55.876+0000] {taskinstance.py:1847} ERROR - Task failed with exception
Traceback (most recent call last):
  File "/home/airflow/.local/lib/python3.7/site-packages/airflow/providers/google/cloud/transfers/local_to_gcs.py", line 93, in execute
    impersonation_chain=self.impersonation_chain,
  File "/home/airflow/.local/lib/python3.7/site-packages/airflow/providers/google/cloud/hooks/gcs.py", line 165, in __init__
    impersonation_chain=impersonation_chain,
  File "/home/airflow/.local/lib/python3.7/site-packages/airflow/providers/google/common/hooks/base_google.py", line 234, in __init__
    self.extras: dict = self.get_connection(self.gcp_conn_id).extra_dejson
  File "/home/airflow/.local/lib/python3.7/site-packages/airflow/hooks/base.py", line 72, in get_connection
    conn = Connection.get_connection_from_secrets(conn_id)
  File "/home/airflow/.local/lib/python3.7/site-packages/airflow/models/connection.py", line 434, in get_connection_from_secrets
    raise AirflowNotFoundException(f"The conn_id `{conn_id}` isn't defined")
airflow.exceptions.AirflowNotFoundException: The conn_id `GoogleBigQuery` isn't defined
[2023-10-03T12:57:55.923+0000] {taskinstance.py:1373} INFO - Marking task as FAILED. dag_id=capstone_project, task_id=upload_file_to_gcs, execution_date=20230927T000000, start_date=20231003T125755, end_date=20231003T125755
[2023-10-03T12:57:55.966+0000] {standard_task_runner.py:109} ERROR - Failed to execute job 325 for task upload_file_to_gcs (The conn_id `GoogleBigQuery` isn't defined; 229)
[2023-10-03T12:57:55.992+0000] {local_task_job_runner.py:232} INFO - Task exited with return code 1
[2023-10-03T12:57:56.039+0000] {taskinstance.py:2674} INFO - 0 downstream tasks scheduled from follow-on schedule check
